Workbook

Sheet Tabuľka 1 Search
B1: 3.3219281
E5: Linear Search O(N) | J5: Binary Search O(log(2)N)
D6: Hľadaná hodnota | E6: Na pozícii | F6: Doba hľadania (ms) | G6: Počet porovnaní | H6: Priemerná doba hľadania(ms) | I6: Priemerný počet porovnaní | J6: Na pozícii | K6: Doba hľadania (ms) | L6: Počet porovnaní | M6: Priemerná doba hľadania(ms) | N6: Priemerný počet porovnaní
B7: 10000000 | C7: 1 | D7: 11347895 | E7: -1 | F7: 173.94562 | G7: 10000000 | H7: =AVERAGE(F7:F16) -> 126.77265 | I7: =AVERAGE(G7:G16) -> 8226390.5 | J7: -1 | K7: 0.010459 | L7: 46 | M7: =AVERAGE(K8:K16) -> 0.0047825565 | N7: =AVERAGE(L7:L16) -> 46
C8: 2 | D8: 5905886 | E8: 1312500 | F8: 21.578917 | G8: 1312501 | J8: 1312500 | K8: 0.0055419951 | L8: 47
C9: 3 | D9: 44654751 | E9: -1 | F9: 150.30629 | G9: 10000000 | J9: -1 | K9: 0.0040419982 | L9: 46
C10: 4 | D10: 41673337 | E10: -1 | F10: 154.93754 | G10: 10000000 | J10: -1 | K10: 0.0044590124 | L10: 46
C11: 5 | D11: 30280813 | E11: -1 | F11: 153.66529 | G11: 10000000 | J11: -1 | K11: 0.0053340045 | L11: 46
C12: 6 | D12: 22463098 | E12: -1 | F12: 149.82308 | G12: 10000000 | J12: -1 | K12: 0.0050829985 | L12: 46
B13: Sada N1= | C13: 7 | D13: 16693615 | E13: -1 | F13: 148.88858 | G13: 10000000 | J13: -1 | K13: 0.0051250099 | L13: 46
C14: 8 | D14: 4282109 | E14: 951403 | F14: 14.060791 | G14: 951404 | J14: 951403 | K14: 0.0051249954 | L14: 45
C15: 9 | D15: 12508030 | E15: -1 | F15: 149.67025 | G15: 10000000 | J15: -1 | K15: 0.0040000014 | L15: 46
C16: 10 | D16: 29207716 | E16: -1 | F16: 150.85017 | G16: 10000000 | J16: -1 | K16: 0.0043329928 | L16: 46
B17: 100000000 | C17: 1 | D17: 124133730 | E17: -1 | F17: 2191.3961 | G17: 100000000 | H17: odhad | I17: odhad | J17: -1 | K17: 0.026041002 | L17: 54 | M17: odhad | N17: odhad
C18: 2 | D18: 417723502 | E18: -1 | F18: 2364.6645 | G18: 100000000 | J18: -1 | K18: 0.023582994 | L18: 54
C19: 3 | D19: 21204324 | E19: -1 | F19: 2332.744 | G19: 100000000 | H19: =H7*$B$17/$B$7 -> 1267.7265 | I19: =I7*$B$17/$B$7 -> 82263905 | J19: -1 | K19: 0.060832986 | L19: 54 | M19: =M7*LOG($B$17,2)/LOG($B$7,2) -> 0.0054657788 | N19: =N7*LOG($B$17,2)/LOG($B$7,2) -> 52.571429
C20: 4 | D20: 165561570 | E20: -1 | F20: 2138.3826 | G20: 100000000 | J20: -1 | K20: 0.018125007 | L20: 54
C21: 5 | D21: 151908981 | E21: -1 | F21: 2149.7798 | G21: 100000000 | J21: -1 | K21: 0.03741699 | L21: 54
C22: 6 | D22: 30651686 | E22: -1 | F22: 2123.257 | G22: 100000000 | H22: skutočná | I22: skutočný | J22: -1 | K22: 0.045541994 | L22: 52 | M22: skutočná | N22: skutočný
B23: Sada N2= | C23: 7 | D23: 218361686 | E23: -1 | F23: 2241.0368 | G23: 100000000 | J23: -1 | K23: 0.020667008 | L23: 54
C24: 8 | D24: 374497767 | E24: -1 | F24: 2175.4325 | G24: 100000000 | H24: =AVERAGE(F17:F26) -> 2130.6141 | I24: =AVERAGE(G17:G26) -> 96884328 | J24: -1 | K24: 0.055291996 | L24: 52 | M24: =AVERAGE(K17:K26) -> 0.035762497 | N24: =AVERAGE(L17:L26) -> 53.1
C25: 9 | D25: 266476667 | E25: -1 | F25: 2131.9186 | G25: 100000000 | J25: -1 | K25: 0.030083 | L25: 54
C26: 10 | D26: 309818306 | E26: 68843275 | F26: 1457.5291 | G26: 68843276 | J26: 68843275 | K26: 0.040041996 | L26: 49
D28: Vyhodnotenie odhadu pre N2 = 100 000 000
H29: LS čas | I29: LS porovnania | M29: BS čas | N29: BS porovnania
D30: odhad / skutočnosť | H30: =H19/H24 -> 0.59500523 | I30: =I19/I24 -> 0.84909404 | M30: =M19/M24 -> 0.15283549 | N30: =N19/N24 -> 0.99004574
D31: 100 % = presný odhad, menej = odhad bol nižší ako skutočnosť, viac = odhad bol vyšší.
D33: Sada | E33: nájdené | F33: nenájdené | G33: rozsah hodnôt v zozname
D34: N1 = 10 000 000 | E34: =COUNTIF(E7:E16,">=0") -> 2 | F34: =COUNTIF(E7:E16,"<0") -> 8 | G34: 3 – 45 005 181
D35: N2 = 100 000 000 | E35: =COUNTIF(E17:E26,">=0") -> 1 | F35: =COUNTIF(E17:E26,"<0") -> 9 | G35: 4 – 449 998 473
D36: Pozícia -1 = hodnota sa v zozname nenachádza. Hľadané hodnoty sú náhodné z celého rozsahu <min, max>, tie isté pre LS aj BS.
E38: časová anomália – nezapočítaná do priemeru (čas na 1 porovnanie > 2 × medián sady)
D39: Odhad LS – O(N): priemer N1 · N2 / N1 Odhad BS – O(log₂N): priemer N1 · log₂N2 / log₂N1

Sheet Tabuľka 2 Sort
D3: Sada N= | F3: 10000 | H3: Random
D4: Doba zoradzovania (ms) | J4: Počet porovnaní (if, while) | P4: Počet presunov dát
B5: Algoritmus | C5: Výpočtová zložitosť | D5: 1 | E5: 2 | F5: 3 | G5: 4 | H5: 5 | I5: Priemer | J5: 1 | K5: 2 | L5: 3 | M5: 4 | N5: 5 | O5: Priemer | P5: 1 | Q5: 2 | R5: 3 | S5: 4 | T5: 5 | U5: Priemer
B6: Bubble Sort | C6: O(n²) | D6: 1714.7422 | E6: 1756.131 | F6: 1733.8341 | G6: 1713.2 | H6: 1730.6537 | I6: =AVERAGE(D6:H6) -> 1729.7122 | J6: 49995000 | K6: 49995000 | L6: 49995000 | M6: 49995000 | N6: 49995000 | O6: =AVERAGE(J6:N6) -> 49995000 | P6: 50256346 | Q6: 50145870 | R6: 49952448 | S6: 49555054 | T6: 50039874 | U6: =AVERAGE(P6:T6) -> 49989918
B7: Select Sort
B8: Insert Sort
B9: Heap Sort
B10: Quick Sort | C10: O(n·log n) | D10: 6.105041 | E10: 6.185708 | F10: 5.854875 | G10: 6.301584 | H10: 5.990667 | I10: =AVERAGE(D10:H10) -> 6.087575 | J10: 241397 | K10: 244551 | L10: 224542 | M10: 269824 | N10: 242310 | O10: =AVERAGE(J10:N10) -> 244524.8 | P10: 327464 | Q10: 315606 | R10: 307178 | S10: 336722 | T10: 321360 | U10: =AVERAGE(P10:T10) -> 321666
B11: Merge Sort
B12: Radix Sort | C12: O(d·n) | D12: 3.701875 | E12: 3.8365 | F12: 3.854458 | G12: 3.791 | H12: 3.913375 | I12: =AVERAGE(D12:H12) -> 3.8194416 | J12: 10005 | K12: 10005 | L12: 10005 | M12: 10005 | N12: 10005 | O12: =AVERAGE(J12:N12) -> 10005 | P12: 50000 | Q12: 50000 | R12: 50000 | S12: 50000 | T12: 50000 | U12: =AVERAGE(P12:T12) -> 50000
D15: Sada N= | F15: 20000 | H15: Random
D16: Doba zoradzovania (ms) | K16: Počet porovnaní (if, while) | R16: Počet presunov dát
B17: Algoritmus | C17: Výpočtová zložitosť | D17: Odhad | E17: 1 | F17: 2 | G17: 3 | H17: 4 | I17: 5 | J17: Priemer | K17: Odhad | L17: 1 | M17: 2 | N17: 3 | O17: 4 | P17: 5 | Q17: Priemer | R17: Odhad | S17: 1 | T17: 2 | U17: 3 | V17: 4 | W17: 5 | X17: Priemer
B18: Bubble Sort | C18: O(n²) | D18: =I6*($F$15/$F$3)^2 -> 6918.8488 | E18: 7069.9141 | F18: 6965.2654 | G18: 6946.326 | H18: 6978.987 | I18: 7000.6101 | J18: =AVERAGE(E18:I18) -> 6992.2205 | K18: =O6*($F$15/$F$3)^2 -> 199980000 | L18: 199990000 | M18: 199990000 | N18: 199990000 | O18: 199990000 | P18: 199990000 | Q18: =AVERAGE(L18:P18) -> 199990000 | R18: =U6*($F$15/$F$3)^2 -> 1.9995967e+08 | S18: 199954450 | T18: 200281694 | U18: 200929414 | V18: 199695076 | W18: 201771668 | X18: =AVERAGE(S18:W18) -> 2.0052646e+08
B19: Select Sort
B20: Insert Sort
B21: Heap Sort
B22: Quick Sort | C22: O(n·log n) | D22: =I10*($F$15*LOG($F$15,2))/($F$3*LOG($F$3,2)) -> 13.091421 | E22: 12.636625 | F22: 12.843041 | G22: 13.884666 | H22: 12.397417 | I22: 12.574417 | J22: =AVERAGE(E22:I22) -> 12.867233 | K22: =O10*($F$15*LOG($F$15,2))/($F$3*LOG($F$3,2)) -> 525854.25 | L22: 503615 | M22: 551381 | N22: 589730 | O22: 495507 | P22: 522148 | Q22: =AVERAGE(L22:P22) -> 532476.2 | R22: =U10*($F$15*LOG($F$15,2))/($F$3*LOG($F$3,2)) -> 691747.56 | S22: 672110 | T22: 705740 | U22: 765584 | V22: 659278 | W22: 680216 | X22: =AVERAGE(S22:W22) -> 696585.6
B23: Merge Sort
B24: Radix Sort | C24: O(d·n) | D24: =I12*$F$15/$F$3 -> 7.6388832 | E24: 7.738917 | F24: 7.728708 | G24: 7.897125 | H24: 7.614375 | I24: 7.673125 | J24: =AVERAGE(E24:I24) -> 7.73045 | K24: =O12*$F$15/$F$3 -> 20010 | L24: 20005 | M24: 20005 | N24: 20005 | O24: 20005 | P24: 20005 | Q24: =AVERAGE(L24:P24) -> 20005 | R24: =U12*$F$15/$F$3 -> 100000 | S24: 100000 | T24: 100000 | U24: 100000 | V24: 100000 | W24: 100000 | X24: =AVERAGE(S24:W24) -> 100000
B27: Vyhodnotenie odhadu pre N = 20 000 (odhad / skutočnosť)
B28: Algoritmus | C28: čas | D28: porovnania | E28: presuny
B29: Bubble Sort | C29: =D18/J18 -> 0.98950666 | D29: =K18/Q18 -> 0.99995 | E29: =R18/X18 -> 0.99717351
B30: Quick Sort | C30: =D22/J22 -> 1.0174232 | D30: =K22/Q22 -> 0.98756386 | E30: =R22/X22 -> 0.99305463
B31: Radix Sort | C31: =D24/J24 -> 0.98815505 | D31: =K24/Q24 -> 1.0002499 | E31: =R24/X24 -> 1
B33: 100 % = presný odhad, menej = odhad bol nižší ako skutočnosť, viac = odhad bol vyšší.
B34: Odhad (stĺpce „Odhad“ sú vzorce): Bubble O(n²) · (N2/N1)² | Quick O(n·log n) · (N2·log₂N2)/(N1·log₂N1) | Radix O(d·n) · N2/N1
B35: Dáta: 5 náhodných sád, hodnoty 0 – 99 999 (pre obe veľkosti rovnaký rozsah → Radix Sort má vždy d = 5 prechodov). Rovnaká sada pre všetky algoritmy.
B36: Podľa zadania sú vybrané Radix Sort, Bubble Sort (z Bubble / Insert / Select) a Quick Sort (z Quick / Merge / Heap).
B37: Porovnania = vykonané podmienky (if, while) porovnávajúce triedené hodnoty; presuny = zápisy prvku na nové miesto (výmena = 2).
C39: časová anomália – nezapočítaná do priemeru (čas > 2 × medián 5 meraní) – v tejto tabuľke sa nevyskytla

Sheet Tabuľka 3 BFS,DFS
B2: Jazdec na šachovnici (zložitosť = O(8^n²)) DFS | J2: Jazdec na šachovnici (zložitosť = O(8^n²)) BFS | R2: Flood Fill (zložitosť = O(n), n = počet pixelov)
B3: n | C3: start x,y | D3: počet skúmaných ciest | F3: čas (ms) | J3: n | K3: start x,y | L3: počet skúmaných ciest | N3: čas (ms) | R3: n (pixely) | S3: algoritmus | T3: čas (ms) | V3: odhad / skutočnosť | W3: útvar
D4: odhad | E4: skutočnosť | F4: odhad | G4: skutočnosť | L4: odhad | M4: skutočnosť | N4: odhad | O4: skutočnosť | T4: odhad | U4: skutočnosť
B5: 4 | C5: 0,0 | D5: X | E5: 17784 | F5: X | G5: 1.799 | J5: 4 | K5: 0,0 | L5: X | M5: 17784 | N5: X | O5: 1.520417 | R5: 8836 | S5: BFS | T5: X | U5: 3.869166 | V5: X | W5: štvorec 100×100
B6: 4 | C6: 1,0 | D6: X | E6: 15080 | F6: X | G6: 1.470792 | J6: 4 | K6: 1,0 | L6: X | M6: 15080 | N6: X | O6: 1.144 | R6: 67800 | S6: BFS | T6: =U$5*R6/R$5 -> 29.688712 | U6: 31.425333 | V6: =T6/U6 -> 0.94473817 | W6: kruh r = 150
B7: 4 | C7: 1,1 | D7: X | E7: 12008 | F7: X | G7: 1.145041 | J7: 4 | K7: 1,1 | L7: X | M7: 12008 | N7: X | O7: 0.891166 | R7: 155109 | S7: BFS | T7: =U$5*R7/R$5 -> 67.920153 | U7: 71.692292 | V7: =T7/U7 -> 0.94738431 | W7: trojuholník 700×450
B8: 5 | C8: 0,0 | D8: =E$5*8^(B8^2-B$5^2) -> 2386928074752 | E8: 410528 | F8: =G$5*8^(B8^2-B$5^2) -> 2.4145769e+08 | G8: 49.261 | J8: 5 | K8: 0,0 | L8: =M$5*8^(J8^2-J$5^2) -> 2386928074752 | M8: 13878200 | N8: =O$5*8^(J8^2-J$5^2) -> 2.0406691e+08 | O8: 1659.9083 | R8: 480700 | S8: BFS | T8: =U$5*R8/R$5 -> 210.49209 | U8: 242.15637 | V8: =T8/U8 -> 0.86924034 | W8: obdĺžnik 880×556
B9: 5 | C9: 1,0 | D9: =E$6*8^(B9^2-B$6^2) -> 2024003338240 | E9: 14635368 | F9: =G$6*8^(B9^2-B$6^2) -> 1.9740636e+08 | G9: 1685.1372 | J9: 5 | K9: 1,0 | L9: =M$6*8^(J9^2-J$6^2) -> 2024003338240 | M9: 14635368 | N9: =O$6*8^(J9^2-J$6^2) -> 1.5354508e+08 | O9: 1721.2992 | R9: 8836 | S9: DFS R | T9: X | U9: 4.4905 | V9: X | W9: štvorec 100×100
B10: 5 | C10: 2,0 | D10: =E$6*8^(B10^2-B$6^2) -> 2024003338240 | E10: 310629 | F10: =G$6*8^(B10^2-B$6^2) -> 1.9740636e+08 | G10: 36.362417 | J10: 5 | K10: 2,0 | L10: =M$6*8^(J10^2-J$6^2) -> 2024003338240 | M10: 11631464 | N10: =O$6*8^(J10^2-J$6^2) -> 1.5354508e+08 | O10: 1338.1215 | R10: 67800 | S10: DFS R | T10: =U$9*R10/R$9 -> 34.456304 | U10: 34.445541 | V10: =T10/U10 -> 1.0003125 | W10: kruh r = 150
B11: 5 | C11: 1,1 | D11: =E$7*8^(B11^2-B$7^2) -> 1611686477824 | E11: 5019640 | F11: =G$7*8^(B11^2-B$7^2) -> 1.536848e+08 | G11: 555.51079 | J11: 5 | K11: 1,1 | L11: =M$7*8^(J11^2-J$7^2) -> 1611686477824 | M11: 11723368 | N11: =O$7*8^(J11^2-J$7^2) -> 1.1961028e+08 | O11: 1345.4117 | R11: 155109 | S11: DFS R | T11: =U$9*R11/R$9 -> 78.82718 | U11: 78.456541 | V11: =T11/U11 -> 1.0047241 | W11: trojuholník 700×450
B12: 5 | C12: 2,1 | D12: =E$7*8^(B12^2-B$7^2) -> 1611686477824 | E12: 8231144 | F12: =G$7*8^(B12^2-B$7^2) -> 1.536848e+08 | G12: 929.20404 | J12: 5 | K12: 2,1 | L12: =M$7*8^(J12^2-J$7^2) -> 1611686477824 | M12: 8231144 | N12: =O$7*8^(J12^2-J$7^2) -> 1.1961028e+08 | O12: 995.62829 | R12: 480700 | S12: DFS R | T12: =U$9*R12/R$9 -> 244.29418 | U12: 241.01008 | V12: =T12/U12 -> 1.0136264 | W12: obdĺžnik 880×556
B13: 5 | C13: 2,2 | D13: =E$7*8^(B13^2-B$7^2) -> 1611686477824 | E13: 283713 | F13: =G$7*8^(B13^2-B$7^2) -> 1.536848e+08 | G13: 30.682416 | J13: 5 | K13: 2,2 | L13: =M$7*8^(J13^2-J$7^2) -> 1611686477824 | M13: 5132104 | N13: =O$7*8^(J13^2-J$7^2) -> 1.1961028e+08 | O13: 620.91079 | R13: 8836 | S13: DFS | T13: X | U13: 3.791 | V13: X | W13: štvorec 100×100
B14: 6 | C14: 0,0 | D14: =E$5*8^(B14^2-B$5^2) -> 2.0503556e+22 | E14: 1277366 | F14: =G$5*8^(B14^2-B$5^2) -> 2.0741058e+18 | G14: 203.86813 | J14: 6 | K14: 0,0 | L14: =M$5*8^(J14^2-J$5^2) -> 2.0503556e+22 | M14: 115000000 | N14: =O$5*8^(J14^2-J$5^2) -> 1.7529214e+18 | O14: 18413.98 | R14: 67800 | S14: DFS | T14: =U$13*R14/R$13 -> 29.088932 | U14: 32.165625 | V14: =T14/U14 -> 0.9043484 | W14: kruh r = 150
B15: 6 | C15: 1,0 | D15: =E$6*8^(B15^2-B$6^2) -> 1.7386056e+22 | E15: 756000019 | F15: =G$6*8^(B15^2-B$6^2) -> 1.6957077e+18 | G15: 120143.26 | J15: 6 | K15: 1,0 | L15: =M$6*8^(J15^2-J$6^2) -> 1.7386056e+22 | M15: 81000000 | N15: =O$6*8^(J15^2-J$6^2) -> 1.3189422e+18 | O15: 11691.559 | R15: 155109 | S15: DFS | T15: =U$13*R15/R$13 -> 66.54801 | U15: 74.133416 | V15: =T15/U15 -> 0.89767899 | W15: trojuholník 700×450
B16: 6 | C16: 2,0 | D16: =E$6*8^(B16^2-B$6^2) -> 1.7386056e+22 | E16: 205620 | F16: =G$6*8^(B16^2-B$6^2) -> 1.6957077e+18 | G16: 33.929292 | J16: 6 | K16: 2,0 | L16: =M$6*8^(J16^2-J$6^2) -> 1.7386056e+22 | M16: 84000000 | N16: =O$6*8^(J16^2-J$6^2) -> 1.3189422e+18 | O16: 12049.641 | R16: 480700 | S16: DFS | T16: =U$13*R16/R$13 -> 206.23967 | U16: 229.27 | V16: =T16/U16 -> 0.8995493 | W16: obdĺžnik 880×556
B17: 6 | C17: 1,1 | D17: =E$7*8^(B17^2-B$7^2) -> 1.3844281e+22 | E17: 14288574 | F17: =G$7*8^(B17^2-B$7^2) -> 1.3201424e+18 | G17: 2134.4712 | J17: 6 | K17: 1,1 | L17: =M$7*8^(J17^2-J$7^2) -> 1.3844281e+22 | M17: 86000000 | N17: =O$7*8^(J17^2-J$7^2) -> 1.0274444e+18 | O17: 12129.667
B18: 6 | C18: 2,1 | D18: =E$7*8^(B18^2-B$7^2) -> 1.3844281e+22 | E18: 783000002 | F18: =G$7*8^(B18^2-B$7^2) -> 1.3201424e+18 | G18: 120081.64 | J18: 6 | K18: 2,1 | L18: =M$7*8^(J18^2-J$7^2) -> 1.3844281e+22 | M18: 87000000 | N18: =O$7*8^(J18^2-J$7^2) -> 1.0274444e+18 | O18: 13065.342 | R18: Odhad = čas prvého (najmenšieho) útvaru · n / n₁ (lineárna zložitosť O(n)).
B19: 6 | C19: 2,2 | D19: =E$7*8^(B19^2-B$7^2) -> 1.3844281e+22 | E19: 5365424 | F19: =G$7*8^(B19^2-B$7^2) -> 1.3201424e+18 | G19: 790.78042 | J19: 6 | K19: 2,2 | L19: =M$7*8^(J19^2-J$7^2) -> 1.3844281e+22 | M19: 143000000 | N19: =O$7*8^(J19^2-J$7^2) -> 1.0274444e+18 | O19: 20787.52 | R19: Merané bez animácie (FloodFillMeranie.py), susedstvo 4, plátno 900 × 576 px, každý útvar na čistom plátne.
B20: 7 | C20: 0,0 | D20: =E$5*8^(B20^2-B$5^2) -> 1.1271949e+34 | E20: 593781 | F20: =G$5*8^(B20^2-B$5^2) -> 1.1402517e+30 | G20: 129.39396 | J20: 7 | K20: 0,0 | L20: =M$5*8^(J20^2-J$5^2) -> 1.1271949e+34 | M20: 75000000 | N20: =O$5*8^(J20^2-J$5^2) -> 9.6367876e+29 | O20: 13044.871 | R20: odhad / skutočnosť: 100 % = presný odhad, menej = odhad bol nižší ako skutočnosť.
B21: 8 | C21: 0,0 | D21: =E$5*8^(B21^2-B$5^2) -> 3.9659645e+47 | E21: 412000011 | F21: =G$5*8^(B21^2-B$5^2) -> 4.0119041e+43 | G21: 120096.2 | J21: 8 | K21: 0,0 | L21: =M$5*8^(J21^2-J$5^2) -> 3.9659645e+47 | M21: 54000000 | N21: =O$5*8^(J21^2-J$5^2) -> 3.3906432e+43 | O21: 9415.4976
B23: Vyhodnotenie odhadu – Jazdec (odhad / skutočnosť)
B24: n | C24: start x,y | D24: DFS: cesta nájdená | E24: DFS cesty odhad/skut. | F24: DFS čas odhad/skut. | G24: BFS: cesta nájdená | H24: BFS cesty odhad/skut. | I24: BFS čas odhad/skut.
B25: =B5 -> 4 | C25: =C5 -> 0,0 | D25: nie | E25: X | F25: X | G25: nie | H25: X | I25: X
B26: =B6 -> 4 | C26: =C6 -> 1,0 | D26: nie | E26: X | F26: X | G26: nie | H26: X | I26: X
B27: =B7 -> 4 | C27: =C7 -> 1,1 | D27: nie | E27: X | F27: X | G27: nie | H27: X | I27: X
B28: =B8 -> 5 | C28: =C8 -> 0,0 | D28: áno | E28: =D8/E8 -> 5814288.1 | F28: =F8/G8 -> 4901599.5 | G28: áno | H28: =L8/M8 -> 171991.19 | I28: =N8/O8 -> 122938.67
B29: =B9 -> 5 | C29: =C9 -> 1,0 | D29: nie | E29: =D9/E9 -> 138295.35 | F29: =F9/G9 -> 117145.57 | G29: nie | H29: =L9/M9 -> 138295.35 | I29: =N9/O9 -> 89203.018
B30: =B10 -> 5 | C30: =C10 -> 2,0 | D30: áno | E30: =D10/E10 -> 6515822.2 | F30: =F10/G10 -> 5428857 | G30: áno | H30: =L10/M10 -> 174011.06 | I30: =N10/O10 -> 114746.74
B31: =B11 -> 5 | C31: =C11 -> 1,1 | D31: áno | E31: =D11/E11 -> 321076.11 | F31: =F11/G11 -> 276654.93 | G31: áno | H31: =L11/M11 -> 137476.4 | I31: =N11/O11 -> 88902.362
B32: =B12 -> 5 | C32: =C12 -> 2,1 | D32: nie | E32: =D12/E12 -> 195803.46 | F32: =F12/G12 -> 165394.03 | G32: nie | H32: =L12/M12 -> 195803.46 | I32: =N12/O12 -> 120135.47
B33: =B13 -> 5 | C33: =C13 -> 2,2 | D33: áno | E33: =D13/E13 -> 5680693.1 | F33: =F13/G13 -> 5008888.5 | G33: áno | H33: =L13/M13 -> 314040.1 | I33: =N13/O13 -> 192636.81
B34: =B14 -> 6 | C34: =C14 -> 0,0 | D34: áno | E34: =D14/E14 -> 1.6051434e+16 | F34: =F14/G14 -> 1.0173762e+16 | G34: prerušené | H34: =L14/M14 -> 1.7829179e+14 | I34: =N14/O14 -> 9.5195144e+13
B35: =B15 -> 6 | C35: =C15 -> 1,0 | D35: prerušené | E35: =D15/E15 -> 2.2997428e+13 | F35: =F15/G15 -> 1.4114048e+13 | G35: prerušené | H35: =L15/M15 -> 2.1464267e+14 | I35: =N15/O15 -> 1.1281149e+14
B36: =B16 -> 6 | C36: =C16 -> 2,0 | D36: áno | E36: =D16/E16 -> 8.4554305e+16 | F36: =F16/G16 -> 4.9977693e+16 | G36: prerušené | H36: =L16/M16 -> 2.0697686e+14 | I36: =N16/O16 -> 1.0945905e+14
B37: =B17 -> 6 | C37: =C17 -> 1,1 | D37: áno | E37: =D17/E17 -> 9.6890574e+14 | F37: =F17/G17 -> 6.1848686e+14 | G37: prerušené | H37: =L17/M17 -> 1.6098002e+14 | I37: =N17/O17 -> 8.4705082e+13
B38: =B18 -> 6 | C38: =C18 -> 2,1 | D38: prerušené | E38: =D18/E18 -> 1.7681075e+13 | F38: =F18/G18 -> 1.0993708e+13 | G38: prerušené | H38: =L18/M18 -> 1.5912967e+14 | I38: =N18/O18 -> 7.8638924e+13
B39: =B19 -> 6 | C39: =C19 -> 2,2 | D39: áno | E39: =D19/E19 -> 2.5802772e+15 | F39: =F19/G19 -> 1.6694171e+15 | G39: prerušené | H39: =L19/M19 -> 9.6813157e+13 | I39: =N19/O19 -> 4.9426022e+13
... B41: =B21 -> 8 | C41: =C21 -> 0,0 | D41: prerušené | E41: =D21/E21 -> 9.6261272e+38 | F41: =F21/G21 -> 3.3405755e+38 | G41: prerušené | H41: =L21/M21 -> 7.3443788e+39 | I41: =N21/O21 -> 3.6011301e+39
B42: Odhad pre n = 5…8 = meranie pre n = 4 s rovnakým typom štartu (roh 0,0 / okraj 1,0 a 2,0 / stred 1,1, 2,1, 2,2) · 8^(n² − 4²).
B43: Pri n = 4 cesta neexistuje, algoritmus prehľadá celý strom → DFS aj BFS majú rovnaký počet skúmaných ciest.
...

Sheet Grafy
A1: Grafy – porovnanie algoritmov a odhadu so skutočnosťou | W1: Zdroj dát pre grafy (vzorce odkazujú na tabuľky 1–3)
A2: Tabuľka 1 – Linear Search vs Binary Search (os Y logaritmická)
W3: Tabuľka 1
W4: Čas hľadania (ms) | X4: Linear Search | Y4: Binary Search
W5: N1 = 10 000 000 – priemer | X5: ='Tabuľka 1 Search'!H7 -> 126.77265 | Y5: ='Tabuľka 1 Search'!M7 -> 0.0047825565
W6: N2 = 100 000 000 – odhad | X6: ='Tabuľka 1 Search'!H19 -> 1267.7265 | Y6: ='Tabuľka 1 Search'!M19 -> 0.0054657788
W7: N2 = 100 000 000 – skutočnosť | X7: ='Tabuľka 1 Search'!H24 -> 2130.6141 | Y7: ='Tabuľka 1 Search'!M24 -> 0.035762497
W9: Počet porovnaní | X9: Linear Search | Y9: Binary Search
W10: N1 = 10 000 000 – priemer | X10: ='Tabuľka 1 Search'!I7 -> 8226390.5 | Y10: ='Tabuľka 1 Search'!N7 -> 46
W11: N2 = 100 000 000 – odhad | X11: ='Tabuľka 1 Search'!I19 -> 82263905 | Y11: ='Tabuľka 1 Search'!N19 -> 52.571429
W12: N2 = 100 000 000 – skutočnosť | X12: ='Tabuľka 1 Search'!I24 -> 96884328 | Y12: ='Tabuľka 1 Search'!N24 -> 53.1
W14: Tabuľka 2
W15: Doba zoraďovania (ms) | X15: Bubble Sort | Y15: Quick Sort | Z15: Radix Sort
W16: N = 10 000 – priemer | X16: ='Tabuľka 2 Sort'!I6 -> 1729.7122 | Y16: ='Tabuľka 2 Sort'!I10 -> 6.087575 | Z16: ='Tabuľka 2 Sort'!I12 -> 3.8194416
W17: N = 20 000 – odhad | X17: ='Tabuľka 2 Sort'!D18 -> 6918.8488 | Y17: ='Tabuľka 2 Sort'!D22 -> 13.091421 | Z17: ='Tabuľka 2 Sort'!D24 -> 7.6388832
W18: N = 20 000 – skutočnosť | X18: ='Tabuľka 2 Sort'!J18 -> 6992.2205 | Y18: ='Tabuľka 2 Sort'!J22 -> 12.867233 | Z18: ='Tabuľka 2 Sort'!J24 -> 7.73045
W20: Počet porovnaní | X20: Bubble Sort | Y20: Quick Sort | Z20: Radix Sort
A21: Tabuľka 2 – Bubble Sort, Quick Sort, Radix Sort (os Y logaritmická) | W21: N = 10 000 – priemer | X21: ='Tabuľka 2 Sort'!O6 -> 49995000 | Y21: ='Tabuľka 2 Sort'!O10 -> 244524.8 | Z21: ='Tabuľka 2 Sort'!O12 -> 10005
W22: N = 20 000 – odhad | X22: ='Tabuľka 2 Sort'!K18 -> 199980000 | Y22: ='Tabuľka 2 Sort'!K22 -> 525854.25 | Z22: ='Tabuľka 2 Sort'!K24 -> 20010
W23: N = 20 000 – skutočnosť | X23: ='Tabuľka 2 Sort'!Q18 -> 199990000 | Y23: ='Tabuľka 2 Sort'!Q22 -> 532476.2 | Z23: ='Tabuľka 2 Sort'!Q24 -> 20005
W25: Počet presunov dát | X25: Bubble Sort | Y25: Quick Sort | Z25: Radix Sort
W26: N = 10 000 – priemer | X26: ='Tabuľka 2 Sort'!U6 -> 49989918 | Y26: ='Tabuľka 2 Sort'!U10 -> 321666 | Z26: ='Tabuľka 2 Sort'!U12 -> 50000
W27: N = 20 000 – odhad | X27: ='Tabuľka 2 Sort'!R18 -> 1.9995967e+08 | Y27: ='Tabuľka 2 Sort'!R22 -> 691747.56 | Z27: ='Tabuľka 2 Sort'!R24 -> 100000
W28: N = 20 000 – skutočnosť | X28: ='Tabuľka 2 Sort'!X18 -> 2.0052646e+08 | Y28: ='Tabuľka 2 Sort'!X22 -> 696585.6 | Z28: ='Tabuľka 2 Sort'!X24 -> 100000
W30: Tabuľka 3 – Jazdec (odhad pre n = 4 nie je – je to základ odhadu)
W31: Počet skúmaných ciest | X31: DFS odhad | Y31: DFS skutočnosť | Z31: BFS odhad | AA31: BFS skutočnosť
W32: 4 (0,0) | Y32: ='Tabuľka 3 BFS,DFS'!E5 -> 17784 | AA32: ='Tabuľka 3 BFS,DFS'!M5 -> 17784
W33: 4 (1,0) | Y33: ='Tabuľka 3 BFS,DFS'!E6 -> 15080 | AA33: ='Tabuľka 3 BFS,DFS'!M6 -> 15080
W34: 4 (1,1) | Y34: ='Tabuľka 3 BFS,DFS'!E7 -> 12008 | AA34: ='Tabuľka 3 BFS,DFS'!M7 -> 12008
W35: 5 (0,0) | X35: ='Tabuľka 3 BFS,DFS'!D8 -> 2386928074752 | Y35: ='Tabuľka 3 BFS,DFS'!E8 -> 410528 | Z35: ='Tabuľka 3 BFS,DFS'!L8 -> 2386928074752 | AA35: ='Tabuľka 3 BFS,DFS'!M8 -> 13878200
W36: 5 (1,0) | X36: ='Tabuľka 3 BFS,DFS'!D9 -> 2024003338240 | Y36: ='Tabuľka 3 BFS,DFS'!E9 -> 14635368 | Z36: ='Tabuľka 3 BFS,DFS'!L9 -> 2024003338240 | AA36: ='Tabuľka 3 BFS,DFS'!M9 -> 14635368
W37: 5 (2,0) | X37: ='Tabuľka 3 BFS,DFS'!D10 -> 2024003338240 | Y37: ='Tabuľka 3 BFS,DFS'!E10 -> 310629 | Z37: ='Tabuľka 3 BFS,DFS'!L10 -> 2024003338240 | AA37: ='Tabuľka 3 BFS,DFS'!M10 -> 11631464
W38: 5 (1,1) | X38: ='Tabuľka 3 BFS,DFS'!D11 -> 1611686477824 | Y38: ='Tabuľka 3 BFS,DFS'!E11 -> 5019640 | Z38: ='Tabuľka 3 BFS,DFS'!L11 -> 1611686477824 | AA38: ='Tabuľka 3 BFS,DFS'!M11 -> 11723368
W39: 5 (2,1) | X39: ='Tabuľka 3 BFS,DFS'!D12 -> 1611686477824 | Y39: ='Tabuľka 3 BFS,DFS'!E12 -> 8231144 | Z39: ='Tabuľka 3 BFS,DFS'!L12 -> 1611686477824 | AA39: ='Tabuľka 3 BFS,DFS'!M12 -> 8231144
W40: 5 (2,2) | X40: ='Tabuľka 3 BFS,DFS'!D13 -> 1611686477824 | Y40: ='Tabuľka 3 BFS,DFS'!E13 -> 283713 | Z40: ='Tabuľka 3 BFS,DFS'!L13 -> 1611686477824 | AA40: ='Tabuľka 3 BFS,DFS'!M13 -> 5132104
W41: 6 (0,0) | X41: ='Tabuľka 3 BFS,DFS'!D14 -> 2.0503556e+22 | Y41: ='Tabuľka 3 BFS,DFS'!E14 -> 1277366 | Z41: ='Tabuľka 3 BFS,DFS'!L14 -> 2.0503556e+22 | AA41: ='Tabuľka 3 BFS,DFS'!M14 -> 115000000
W42: 6 (1,0) | X42: ='Tabuľka 3 BFS,DFS'!D15 -> 1.7386056e+22 | Y42: ='Tabuľka 3 BFS,DFS'!E15 -> 756000019 | Z42: ='Tabuľka 3 BFS,DFS'!L15 -> 1.7386056e+22 | AA42: ='Tabuľka 3 BFS,DFS'!M15 -> 81000000
W43: 6 (2,0) | X43: ='Tabuľka 3 BFS,DFS'!D16 -> 1.7386056e+22 | Y43: ='Tabuľka 3 BFS,DFS'!E16 -> 205620 | Z43: ='Tabuľka 3 BFS,DFS'!L16 -> 1.7386056e+22 | AA43: ='Tabuľka 3 BFS,DFS'!M16 -> 84000000
W44: 6 (1,1) | X44: ='Tabuľka 3 BFS,DFS'!D17 -> 1.3844281e+22 | Y44: ='Tabuľka 3 BFS,DFS'!E17 -> 14288574 | Z44: ='Tabuľka 3 BFS,DFS'!L17 -> 1.3844281e+22 | AA44: ='Tabuľka 3 BFS,DFS'!M17 -> 86000000
W45: 6 (2,1) | X45: ='Tabuľka 3 BFS,DFS'!D18 -> 1.3844281e+22 | Y45: ='Tabuľka 3 BFS,DFS'!E18 -> 783000002 | Z45: ='Tabuľka 3 BFS,DFS'!L18 -> 1.3844281e+22 | AA45: ='Tabuľka 3 BFS,DFS'!M18 -> 87000000
...
